ERROR:tornado.application:Uncaught exception GET /index?userid=xuke (127.0.0.1)
HTTPServerRequest(protocol='http', host='127.0.0.1:7601', method='GET', uri='/index?userid=xuke', version='HTTP/1.1', remote_ip='127.0.0.1')
Traceback (most recent call last):
  File "/usr/local/lib64/python3.6/site-packages/tornado/web.py", line 1697, in _execute
    result = method(*self.path_args, **self.path_kwargs)
  File "/app/engine/main.py", line 57, in get
    doc_list.sort(key="score",reserve=False)
TypeError: 'reserve' is an invalid keyword argument for this function
ERROR:tornado.access:500 GET /index?userid=xuke (127.0.0.1) 73.92ms
WARNING:elasticsearch:GET http://119.3.252.18:8010/doc/keyword/_search [status:N/A request:0.001s]
Traceback (most recent call last):
  File "/usr/local/lib/python3.6/site-packages/urllib3/connection.py", line 160, in _new_conn
    (self._dns_host, self.port), self.timeout, **extra_kw)
  File "/usr/local/lib/python3.6/site-packages/urllib3/util/connection.py", line 80, in create_connection
    raise err
  File "/usr/local/lib/python3.6/site-packages/urllib3/util/connection.py", line 70, in create_connection
    sock.connect(sa)
ConnectionRefusedError: [Errno 111] Connection refused

During handling of the above exception, another exception occurred:

Traceback (most recent call last):
  File "/usr/local/lib/python3.6/site-packages/elasticsearch/connection/http_urllib3.py", line 95, in perform_request
    response = self.pool.urlopen(method, url, body, retries=False, headers=self.headers, **kw)
  File "/usr/local/lib/python3.6/site-packages/urllib3/connectionpool.py", line 641, in urlopen
    _stacktrace=sys.exc_info()[2])
  File "/usr/local/lib/python3.6/site-packages/urllib3/util/retry.py", line 344, in increment
    raise six.reraise(type(error), error, _stacktrace)
  File "/usr/local/lib/python3.6/site-packages/urllib3/packages/six.py", line 686, in reraise
    raise value
  File "/usr/local/lib/python3.6/site-packages/urllib3/connectionpool.py", line 603, in urlopen
    chunked=chunked)
  File "/usr/local/lib/python3.6/site-packages/urllib3/connectionpool.py", line 355, in _make_request
    conn.request(method, url, **httplib_request_kw)
  File "/usr/lib64/python3.6/http/client.py", line 1239, in request
    self._send_request(method, url, body, headers, encode_chunked)
  File "/usr/lib64/python3.6/http/client.py", line 1285, in _send_request
    self.endheaders(body, encode_chunked=encode_chunked)
  File "/usr/lib64/python3.6/http/client.py", line 1234, in endheaders
    self._send_output(message_body, encode_chunked=encode_chunked)
  File "/usr/lib64/python3.6/http/client.py", line 1026, in _send_output
    self.send(msg)
  File "/usr/lib64/python3.6/http/client.py", line 964, in send
    self.connect()
  File "/usr/local/lib/python3.6/site-packages/urllib3/connection.py", line 183, in connect
    conn = self._new_conn()
  File "/usr/local/lib/python3.6/site-packages/urllib3/connection.py", line 169, in _new_conn
    self, "Failed to establish a new connection: %s" % e)
urllib3.exceptions.NewConnectionError: <urllib3.connection.HTTPConnection object at 0x7f9457bda780>: Failed to establish a new connection: [Errno 111] Connection refused
WARNING:elasticsearch:GET http://119.3.252.18:8010/doc/keyword/_search [status:N/A request:0.001s]
Traceback (most recent call last):
  File "/usr/local/lib/python3.6/site-packages/urllib3/connection.py", line 160, in _new_conn
    (self._dns_host, self.port), self.timeout, **extra_kw)
  File "/usr/local/lib/python3.6/site-packages/urllib3/util/connection.py", line 80, in create_connection
    raise err
  File "/usr/local/lib/python3.6/site-packages/urllib3/util/connection.py", line 70, in create_connection
    sock.connect(sa)
ConnectionRefusedError: [Errno 111] Connection refused

During handling of the above exception, another exception occurred:

Traceback (most recent call last):
  File "/usr/local/lib/python3.6/site-packages/elasticsearch/connection/http_urllib3.py", line 95, in perform_request
    response = self.pool.urlopen(method, url, body, retries=False, headers=self.headers, **kw)
  File "/usr/local/lib/python3.6/site-packages/urllib3/connectionpool.py", line 641, in urlopen
    _stacktrace=sys.exc_info()[2])
  File "/usr/local/lib/python3.6/site-packages/urllib3/util/retry.py", line 344, in increment
    raise six.reraise(type(error), error, _stacktrace)
  File "/usr/local/lib/python3.6/site-packages/urllib3/packages/six.py", line 686, in reraise
    raise value
  File "/usr/local/lib/python3.6/site-packages/urllib3/connectionpool.py", line 603, in urlopen
    chunked=chunked)
  File "/usr/local/lib/python3.6/site-packages/urllib3/connectionpool.py", line 355, in _make_request
    conn.request(method, url, **httplib_request_kw)
  File "/usr/lib64/python3.6/http/client.py", line 1239, in request
    self._send_request(method, url, body, headers, encode_chunked)
  File "/usr/lib64/python3.6/http/client.py", line 1285, in _send_request
    self.endheaders(body, encode_chunked=encode_chunked)
  File "/usr/lib64/python3.6/http/client.py", line 1234, in endheaders
    self._send_output(message_body, encode_chunked=encode_chunked)
  File "/usr/lib64/python3.6/http/client.py", line 1026, in _send_output
    self.send(msg)
  File "/usr/lib64/python3.6/http/client.py", line 964, in send
    self.connect()
  File "/usr/local/lib/python3.6/site-packages/urllib3/connection.py", line 183, in connect
    conn = self._new_conn()
  File "/usr/local/lib/python3.6/site-packages/urllib3/connection.py", line 169, in _new_conn
    self, "Failed to establish a new connection: %s" % e)
urllib3.exceptions.NewConnectionError: <urllib3.connection.HTTPConnection object at 0x7f9457bda6a0>: Failed to establish a new connection: [Errno 111] Connection refused
WARNING:elasticsearch:GET http://119.3.252.18:8010/doc/keyword/_search [status:N/A request:0.001s]
Traceback (most recent call last):
  File "/usr/local/lib/python3.6/site-packages/urllib3/connection.py", line 160, in _new_conn
    (self._dns_host, self.port), self.timeout, **extra_kw)
  File "/usr/local/lib/python3.6/site-packages/urllib3/util/connection.py", line 80, in create_connection
    raise err
  File "/usr/local/lib/python3.6/site-packages/urllib3/util/connection.py", line 70, in create_connection
    sock.connect(sa)
ConnectionRefusedError: [Errno 111] Connection refused

During handling of the above exception, another exception occurred:

Traceback (most recent call last):
  File "/usr/local/lib/python3.6/site-packages/elasticsearch/connection/http_urllib3.py", line 95, in perform_request
    response = self.pool.urlopen(method, url, body, retries=False, headers=self.headers, **kw)
  File "/usr/local/lib/python3.6/site-packages/urllib3/connectionpool.py", line 641, in urlopen
    _stacktrace=sys.exc_info()[2])
  File "/usr/local/lib/python3.6/site-packages/urllib3/util/retry.py", line 344, in increment
    raise six.reraise(type(error), error, _stacktrace)
  File "/usr/local/lib/python3.6/site-packages/urllib3/packages/six.py", line 686, in reraise
    raise value
  File "/usr/local/lib/python3.6/site-packages/urllib3/connectionpool.py", line 603, in urlopen
    chunked=chunked)
  File "/usr/local/lib/python3.6/site-packages/urllib3/connectionpool.py", line 355, in _make_request
    conn.request(method, url, **httplib_request_kw)
  File "/usr/lib64/python3.6/http/client.py", line 1239, in request
    self._send_request(method, url, body, headers, encode_chunked)
  File "/usr/lib64/python3.6/http/client.py", line 1285, in _send_request
    self.endheaders(body, encode_chunked=encode_chunked)
  File "/usr/lib64/python3.6/http/client.py", line 1234, in endheaders
    self._send_output(message_body, encode_chunked=encode_chunked)
  File "/usr/lib64/python3.6/http/client.py", line 1026, in _send_output
    self.send(msg)
  File "/usr/lib64/python3.6/http/client.py", line 964, in send
    self.connect()
  File "/usr/local/lib/python3.6/site-packages/urllib3/connection.py", line 183, in connect
    conn = self._new_conn()
  File "/usr/local/lib/python3.6/site-packages/urllib3/connection.py", line 169, in _new_conn
    self, "Failed to establish a new connection: %s" % e)
urllib3.exceptions.NewConnectionError: <urllib3.connection.HTTPConnection object at 0x7f9457bdab00>: Failed to establish a new connection: [Errno 111] Connection refused
WARNING:elasticsearch:GET http://119.3.252.18:8010/doc/keyword/_search [status:N/A request:0.001s]
Traceback (most recent call last):
  File "/usr/local/lib/python3.6/site-packages/urllib3/connection.py", line 160, in _new_conn
    (self._dns_host, self.port), self.timeout, **extra_kw)
  File "/usr/local/lib/python3.6/site-packages/urllib3/util/connection.py", line 80, in create_connection
    raise err
  File "/usr/local/lib/python3.6/site-packages/urllib3/util/connection.py", line 70, in create_connection
    sock.connect(sa)
ConnectionRefusedError: [Errno 111] Connection refused

During handling of the above exception, another exception occurred:

Traceback (most recent call last):
  File "/usr/local/lib/python3.6/site-packages/elasticsearch/connection/http_urllib3.py", line 95, in perform_request
    response = self.pool.urlopen(method, url, body, retries=False, headers=self.headers, **kw)
  File "/usr/local/lib/python3.6/site-packages/urllib3/connectionpool.py", line 641, in urlopen
    _stacktrace=sys.exc_info()[2])
  File "/usr/local/lib/python3.6/site-packages/urllib3/util/retry.py", line 344, in increment
    raise six.reraise(type(error), error, _stacktrace)
  File "/usr/local/lib/python3.6/site-packages/urllib3/packages/six.py", line 686, in reraise
    raise value
  File "/usr/local/lib/python3.6/site-packages/urllib3/connectionpool.py", line 603, in urlopen
    chunked=chunked)
  File "/usr/local/lib/python3.6/site-packages/urllib3/connectionpool.py", line 355, in _make_request
    conn.request(method, url, **httplib_request_kw)
  File "/usr/lib64/python3.6/http/client.py", line 1239, in request
    self._send_request(method, url, body, headers, encode_chunked)
  File "/usr/lib64/python3.6/http/client.py", line 1285, in _send_request
    self.endheaders(body, encode_chunked=encode_chunked)
  File "/usr/lib64/python3.6/http/client.py", line 1234, in endheaders
    self._send_output(message_body, encode_chunked=encode_chunked)
  File "/usr/lib64/python3.6/http/client.py", line 1026, in _send_output
    self.send(msg)
  File "/usr/lib64/python3.6/http/client.py", line 964, in send
    self.connect()
  File "/usr/local/lib/python3.6/site-packages/urllib3/connection.py", line 183, in connect
    conn = self._new_conn()
  File "/usr/local/lib/python3.6/site-packages/urllib3/connection.py", line 169, in _new_conn
    self, "Failed to establish a new connection: %s" % e)
urllib3.exceptions.NewConnectionError: <urllib3.connection.HTTPConnection object at 0x7f9457bda5f8>: Failed to establish a new connection: [Errno 111] Connection refused
ERROR:tornado.application:Uncaught exception GET /index?userid=xuke (127.0.0.1)
HTTPServerRequest(protocol='http', host='127.0.0.1:7601', method='GET', uri='/index?userid=xuke', version='HTTP/1.1', remote_ip='127.0.0.1')
Traceback (most recent call last):
  File "/usr/local/lib/python3.6/site-packages/urllib3/connection.py", line 160, in _new_conn
    (self._dns_host, self.port), self.timeout, **extra_kw)
  File "/usr/local/lib/python3.6/site-packages/urllib3/util/connection.py", line 80, in create_connection
    raise err
  File "/usr/local/lib/python3.6/site-packages/urllib3/util/connection.py", line 70, in create_connection
    sock.connect(sa)
ConnectionRefusedError: [Errno 111] Connection refused

During handling of the above exception, another exception occurred:

Traceback (most recent call last):
  File "/usr/local/lib/python3.6/site-packages/elasticsearch/connection/http_urllib3.py", line 95, in perform_request
    response = self.pool.urlopen(method, url, body, retries=False, headers=self.headers, **kw)
  File "/usr/local/lib/python3.6/site-packages/urllib3/connectionpool.py", line 641, in urlopen
    _stacktrace=sys.exc_info()[2])
  File "/usr/local/lib/python3.6/site-packages/urllib3/util/retry.py", line 344, in increment
    raise six.reraise(type(error), error, _stacktrace)
  File "/usr/local/lib/python3.6/site-packages/urllib3/packages/six.py", line 686, in reraise
    raise value
  File "/usr/local/lib/python3.6/site-packages/urllib3/connectionpool.py", line 603, in urlopen
    chunked=chunked)
  File "/usr/local/lib/python3.6/site-packages/urllib3/connectionpool.py", line 355, in _make_request
    conn.request(method, url, **httplib_request_kw)
  File "/usr/lib64/python3.6/http/client.py", line 1239, in request
    self._send_request(method, url, body, headers, encode_chunked)
  File "/usr/lib64/python3.6/http/client.py", line 1285, in _send_request
    self.endheaders(body, encode_chunked=encode_chunked)
  File "/usr/lib64/python3.6/http/client.py", line 1234, in endheaders
    self._send_output(message_body, encode_chunked=encode_chunked)
  File "/usr/lib64/python3.6/http/client.py", line 1026, in _send_output
    self.send(msg)
  File "/usr/lib64/python3.6/http/client.py", line 964, in send
    self.connect()
  File "/usr/local/lib/python3.6/site-packages/urllib3/connection.py", line 183, in connect
    conn = self._new_conn()
  File "/usr/local/lib/python3.6/site-packages/urllib3/connection.py", line 169, in _new_conn
    self, "Failed to establish a new connection: %s" % e)
urllib3.exceptions.NewConnectionError: <urllib3.connection.HTTPConnection object at 0x7f9457bda5f8>: Failed to establish a new connection: [Errno 111] Connection refused

During handling of the above exception, another exception occurred:

Traceback (most recent call last):
  File "/usr/local/lib64/python3.6/site-packages/tornado/web.py", line 1697, in _execute
    result = method(*self.path_args, **self.path_kwargs)
  File "/app/engine/main.py", line 53, in get
  File "/app/engine/recall_random.py", line 24, in get
    rsp_body = es.search(index="doc", doc_type="keyword", body=param_body)
  File "/usr/local/lib/python3.6/site-packages/elasticsearch/client/utils.py", line 69, in _wrapped
    return func(*args, params=params, **kwargs)
  File "/usr/local/lib/python3.6/site-packages/elasticsearch/client/__init__.py", line 539, in search
    doc_type, '_search'), params=params, body=body)
  File "/usr/local/lib/python3.6/site-packages/elasticsearch/transport.py", line 327, in perform_request
    status, headers, data = connection.perform_request(method, url, params, body, ignore=ignore, timeout=timeout)
  File "/usr/local/lib/python3.6/site-packages/elasticsearch/connection/http_urllib3.py", line 106, in perform_request
    raise ConnectionError('N/A', str(e), e)
elasticsearch.exceptions.ConnectionError: ConnectionError(<urllib3.connection.HTTPConnection object at 0x7f9457bda5f8>: Failed to establish a new connection: [Errno 111] Connection refused) caused by: NewConnectionError(<urllib3.connection.HTTPConnection object at 0x7f9457bda5f8>: Failed to establish a new connection: [Errno 111] Connection refused)
ERROR:tornado.access:500 GET /index?userid=xuke (127.0.0.1) 6.77ms
